Workbook

Sheet Set25
A1: PERÍODO 05 á 14/SET/25 | C1: =D2+E2+F2+G2+H2+I2+J2+M2+P2 -> -3986.46 | D1: SPOT | E1: ITAU | F1: LUCILA | G1: LUCILA2 | H1: CAIXA | I1: CARTAO | J1: VENDAS | K1: GASOLINA | N1: ETANOL | Q1: ERALDO | R1: LUIZ F. | S1: LUCILA | T1: DIVIDA | U1: WL | V1: WL | AO1: Total | AP1: Saldo Total | AQ1: Saldo Edson | AR1: Saldo Master
B2: Saldo Inicial do dia | C2: =D2+E2+F2+G2+H2+I2+J2+M2+P2+SUM(Q2:AN2) -> -296310.2 | D2: 94.13 | E2: -37907.13 | F2: 6.19 | I2: 8907.15 | J2: 0 | K2: 2164 | L2: 5.2 | M2: =K2*L2 -> 11252.8 | N2: 3848 | O2: 3.55 | P2: =N2*O2 -> 13660.4 | Q2: 0 | S2: 0 | T2: -19288.14 | U2: =-11335.6-11265.54-11265.54-11268.92-12900-12900-12900-12900-11669-11665.5-11665.5-11665.5-11665.5-11669-8825-8825-11798.82-11798.82-11802.36-17750-17750-17750 -> -273035.6 | V2: 0 | W2: 0 | X2: 0 | Y2: 0 | AM2: 0 | AO2: =D2+E2+F2+G2+H2+I2+J2+M2+P2+SUM(Q2:AN2) -> -296310.2 | AP2: =#REF! -> #REF! | AQ2: =#REF! -> #REF! | AR2: =AP2-AQ2 -> #REF!
A3: 45905 | B3: Credito Vendas Cartão | D3: 8678.72 | I3: =-D3 -> -8678.72 | AQ3: Saidas | AR3: #REF!
B4: Desconto taxas Cartão | I4: =-I2-I3 -> -228.43 | AQ4: Saidas | AR4: #REF!
B5: Pix e depósitos Banco Itaú | E5: =50+20+10+320+395+1000+2000+10+100+5+50+700+20.7+20+20+50+100+170+30+50+50+25+50+70+20 -> 5335.7 | H5: =-E5 -> -5335.7 | M5: =K5*L5 -> 0 | P5: =N5*O5 -> 0 | AQ5: Saidas | AR5: #REF!
B6: Pix e depósitos Banco Itaú - Lucila | E6: =7700+1000 -> 8700 | G6: =-E6 -> -8700 | M6: =K6*L6 -> 0 | P6: =N6*O6 -> 0
B7: Pag boleto WL NF 73289 3/3 VENC 01/08 | E7: -11335.6 | M7: =K7*L7 -> 0 | P7: =N7*O7 -> 0 | U7: =-E7 -> 11335.6 | AQ7: Saidas | AR7: #REF!
B8: Crediario Emprestimo 1/6 parcelas 3.214,69 | E8: =-1141.12-5-50-700-20.7-20-20-50-100-170-30-50-50-25-50-732.87 -> -3214.69 | M8: =K8*L8 -> 0 | P8: =N8*O8 -> 0 | T8: =-E8 -> 3214.69 | AQ8: Saidas | AR8: #REF!
B9: Pag Pantoja & Co (mercado) | E9: -52.26 | P9: =N9*O9 -> 0 | AQ9: Saidas | AR9: #REF!
B10: Pix Lucila | D10: -300 | G10: =-D10 -> 300 | P10: =N10*O10 -> 0
B11: Tarifa pix | D11: -4.9 | P11: =N11*O11 -> 0
B12: Pix Eraldo Macedo | D12: 48200 | P12: =N12*O12 -> 0 | Q12: =-D12 -> -48200
B13: Tarifa pix recebido 0,8% | D13: -385.6 | P13: =N13*O13 -> 0
B14: Pag. NF 81861 Petroriente 10x4,82 GC (Eraldo) | D14: -48200 | K14: 10000 | L14: 4.82 | M14: =K14*L14 -> 48200 | P14: =N14*O14 -> 0
B15: Tarifa pix enviado Petroriente | D15: -4.9 | P15: =N15*O15 -> 0
B16: Pix Lucila (NUBANK) | D16: -8000 | G16: =-D16 -> 8000 | P16: =N16*O16 -> 0
B17: Tarifa pix enviado Petroriente | D17: -4.9
B18: Compra WL 20x3,67 EH 6x12.233,33 NF 81639 | N18: 20000 | O18: 3.67 | P18: =N18*O18 -> 73400 | V18: =-P18 -> -73400
B19: Cesta básica (dinheiro) | H19: -791.28
B20: Vale refeição 5x767,00 | H20: -3835
AP21: =#REF! -> #REF!
B22: Venda de Gasolina | J22: =-M22 -> 7208.88 | K22: -1226 | L22: 5.88 | M22: =K22*L22 -> -7208.88 | AP22: =#REF! -> #REF!
B23: Venda de Etanol | J23: =-P23 -> 7065.48 | N23: -1821 | O23: 3.88 | P23: =N23*O23 -> -7065.48 | AP23: =#REF! -> #REF!
B24: Separação Cartão/Outros | H24: =-J24-I24 -> 4369.19 | I24: 9905.17 | J24: =-SUM(J22:J23) -> -14274.36 | AO24: =A2 -> 0 | AP24: =#REF! -> #REF!
B25: Ajuste estoque e valor diário (lucro embutido) | K25: 118 | M25: =(K28*4.8876027)-M14-M2-M22 -> 1793.4155 | N25: 164 | P25: =(N28*3.650637)-P18-P2-P23 -> 1016.3657 | AP25: =#REF! -> #REF!
AO26: =A3 -> 45905 | AP26: =#REF! -> #REF!
B27: Saldo Giro no dia | C27: =D28+E28+F28+G28+H28+I28+J28+M28+P28 -> 100565.77 | M27: =K27*L27 -> 0 | P27: =N27*O27 -> 0 | AO27: =SUM($Q2:AN27) -> -399373.45 | AS27: TERCEIROS
B28: Saldo Líquido do dia | C28: =AO28 -> -298807.68 | D28: =SUM(D2:D27) -> 72.55 | E28: =SUM(E2:E27) -> -38473.98 | F28: =SUM(F2:F27) -> 6.19 | G28: =SUM(G2:G27) -> -400 | H28: =SUM(H2:H27) -> -5592.79 | I28: =SUM(I2:I27) -> 9905.17 | J28: =SUM(J2:J27) -> 0 | K28: =SUM(K2:K27) -> 11056 | L28: =M28/K28 -> 4.8876031 | M28: =ROUND(SUM(M2:M27),2) -> 54037.34 | N28: =SUM(N2:N27) -> 22191 | O28: =P28/N28 -> 3.6506372 | P28: =ROUND(SUM(P2:P27),2) -> 81011.29 | Q28: =SUM(Q2:Q27) -> -48200 | R28: =SUM(R2:R27) -> 0 | S28: =SUM(S2:S27) -> 0 | T28: =SUM(T2:T27) -> -16073.45 | U28: =SUM(U2:U27) -> -261700 | V28: =SUM(V2:V27) -> -73400 | W28: =SUM(W2:W27) -> 0 | X28: =SUM(X2:X27) -> 0 | ... AH28: =SUM(AH2:AH27) -> 0 | AJ28: =SUM(AJ2:AJ27) -> 0 | AK28: =SUM(AK2:AK27) -> 0 | AL28: =SUM(AL2:AL27) -> 0 | AM28: =SUM(AM2:AM27) -> 0 | AN28: =SUM(AN2:AN27) -> 0 | AO28: =D28+E28+F28+G28+H28+I28+J28+M28+P28+SUM(Q28:AN28) -> -298807.68 | AS28: SALDO C/C
A29: =A3+1 -> 45906 | B29: Credito Vendas Cartão | D29: 9693.15 | I29: -9693.15 | AP29: =#REF! -> #REF!
B30: Desconto taxas Cartão | I30: =-I28-I29 -> -212.02
B31: Luiz Neto (BB) | D31: -6000 | R31: =-D31 -> 6000
B32: Tarifa pix Luiz Neto | D32: -4.9
B33: Pag boleto Elektro (postp) | D33: -182.46
B34: Pag boleto | D34: -195
B35: Pag boleto | D35: -385.5
AP36: =#REF! -> #REF!
B37: Venda de Gasolina | J37: =-M37 -> 10548 | K37: -1800 | L37: 5.86 | M37: =K37*L37 -> -10548 | AP37: =#REF! -> #REF!
B38: Venda de Etanol | J38: =-P38 -> 9607.54 | N38: -2489 | O38: 3.86 | P38: =N38*O38 -> -9607.54 | AP38: =#REF! -> #REF!
B39: Separação Cartão/Outros | H39: =-J39-I39 -> 6047.48 | I39: 14108.06 | J39: =-SUM(J37:J38) -> -20155.54 | AP39: =#REF! -> #REF!
B40: Ajuste estoque e valor diário (lucro embutido) | K40: 0 | M40: =(K43*L28)-M28-M37 -> 1750.3144 | N40: -52 | P40: =(N43*O28)-P28-P38 -> 331.27089 | AP40: =#REF! -> #REF!
...

Sheet Out25
A1: PERÍODO 01 á 31/OUT/25 | C1: =D2+E2+F2+G2+H2+I2+J2+M2+P2 -> 51048.21 | D1: SPOT | E1: ITAU | F1: LUCILA | G1: HADEN | H1: CAIXA | I1: CARTAO | J1: VENDAS | K1: GASOLINA | N1: ETANOL | Q1: ERALDO | R1: LUIZ F. | S1: LUCILA | T1: DIVIDA | U1: AVANT | V1: WL | AO1: Total | AP1: Saldo Total | AQ1: Saldo Edson | AR1: Saldo Master
B2: Saldo Inicial do dia | C2: =D2+E2+F2+G2+H2+I2+J2+M2+P2+SUM(Q2:AN2) -> -316079.67 | D2: ='Set25'!D458 -> 20130.38 | E2: ='Set25'!E458 -> -20251.87 | F2: ='Set25'!F458 -> 649.16 | G2: 0 | H2: ='Set25'!H458 -> -32.68 | I2: ='Set25'!I458 -> 11179.04 | J2: ='Set25'!J458 -> 0 | K2: ='Set25'!K458 -> 5095 | L2: ='Set25'!L458 -> 4.9769323 | M2: ='Set25'!M458 -> 25357.47 | N2: ='Set25'!N458 -> 3969 | O2: ='Set25'!O458 -> 3.531547 | ... AN2: ='Set25'!AN458 -> 0 | AO2: =D2+E2+F2+G2+H2+I2+J2+M2+P2+SUM(Q2:AN2) -> -316079.67 | AP2: =#REF! -> #REF! | AQ2: =#REF! -> #REF! | AR2: =AP2-AQ2 -> #REF!
A3: 45931 | B3: Credito Vendas Cartão | D3: 10926.8 | I3: =-D3 -> -10926.8 | AQ3: Saidas | AR3: #REF!
B4: Desconto taxas Cartão | I4: =-I2-I3 -> -252.24 | AQ4: Saidas | AR4: #REF!
B5: Mensalidade POS | D5: -70 | AQ5: Saidas | AR5: #REF!
B6: Pix e depósitos Banco Itaú | E6: =50+25+50+25+260+30+30+10+25+50+0.39+30+11.25+40+20+30+30+10+20+20+519.93+100+50+65+15+40+60 -> 1616.57 | H6: =-E6 -> -1616.57 | AQ6: Saidas | AR6: #REF!
B7: Pix e depósitos Banco Itaú - Lucila | E7: =654+2000+2000+1500 -> 6154 | H7: =-E7 -> -6154
B8: Transf. Lucila | E8: -9900 | F8: =-E8 -> 9900 | AQ8: Saidas | AR8: #REF!
B9: Transf. Lucila Regina Ceregato Correa | D9: -30900 | F9: =-D9 -> 30900 | AQ9: Saidas | AR9: #REF!
B10: NF 99547 WL 15x3,55 EH 2X26625,00 | N10: 15000 | O10: 3.55 | P10: =N10*O10 -> 53250 | V10: =-P10 -> -53250
AP11: =#REF! -> #REF!
B12: Venda de Gasolina | J12: =-M12 -> 6612.18 | K12: -1142 | L12: 5.79 | M12: =K12*L12 -> -6612.18 | AP12: =#REF! -> #REF!
B13: Venda de Etanol | J13: =-P13 -> 8974.72 | N13: -2368 | O13: 3.79 | P13: =N13*O13 -> -8974.72 | AP13: =#REF! -> #REF!
B14: Separação Cartão/Outros | H14: =-J14-I14 -> 6038.9 | I14: 9548 | J14: =-SUM(J12:J13) -> -15586.9 | AO14: =A2 -> 0 | AP14: =#REF! -> #REF!
B15: Ajuste estoque e valor diário (lucro embutido) | K15: -53 | M15: =(K18*L2)-M2-M12 -> 664.74592 | N15: 83 | P15: =(N18*((P2+P10)/(N2+N10))-P10-P2-P13) -> 871.79247 | AP15: =#REF! -> #REF!
AO16: =A3 -> 45931 | AP16: =#REF! -> #REF!
B17: Saldo Giro no dia | C17: =D18+E18+F18+G18+H18+I18+J18+M18+P18 -> 105512.51 | M17: =K17*L17 -> 0 | P17: =N17*O17 -> 0 | AO17: =SUM($Q2:AN17) -> -420377.88 | AS17: TERCEIROS
B18: Saldo Líquido do dia | C18: =AO18 -> -314865.37 | D18: =SUM(D2:D17) -> 87.18 | E18: =SUM(E2:E17) -> -22381.3 | F18: =SUM(F2:F17) -> 41449.16 | G18: =SUM(G2:G17) -> 0 | H18: =SUM(H2:H17) -> -1764.35 | I18: =SUM(I2:I17) -> 9548 | J18: =SUM(J2:J17) -> 0 | K18: =SUM(K2:K17) -> 3900 | L18: =M18/K18 -> 4.9769333 | M18: =ROUND(SUM(M2:M17),2) -> 19410.04 | N18: =SUM(N2:N17) -> 16684 | O18: =P18/N18 -> 3.5461388 | P18: =ROUND(SUM(P2:P17),2) -> 59163.78 | Q18: =SUM(Q2:Q17) -> -248820 | R18: =SUM(R2:R17) -> 7865.57 | S18: =SUM(S2:S17) -> 0 | T18: =SUM(T2:T17) -> -16073.45 | U18: =SUM(U2:U17) -> 0 | V18: =SUM(V2:V17) -> -163350 | W18: =SUM(W2:W17) -> 0 | X18: =SUM(X2:X17) -> 0 | ... AH18: =SUM(AH2:AH17) -> 0 | AJ18: =SUM(AJ2:AJ17) -> 0 | AK18: =SUM(AK2:AK17) -> 0 | AL18: =SUM(AL2:AL17) -> 0 | AM18: =SUM(AM2:AM17) -> 0 | AN18: =SUM(AN2:AN17) -> 0 | AO18: =D18+E18+F18+G18+H18+I18+J18+M18+P18+SUM(Q18:AN18) -> -314865.37 | AS18: SALDO C/C
A19: =A3+1 -> 45932 | B19: Credito Vendas Cartão | D19: 9310.7 | I19: =-D19 -> -9310.7 | AP19: =#REF! -> #REF!
B20: Desconto taxas Cartão | I20: =-I18-I19 -> -237.3
B21: Pix e depósitos Banco Itaú | E21: =150+50+117+50+50+100+20+10+100+10+50+19+50+20+10+10+10+100+185+30 -> 1141 | H21: =-E21 -> -1141 | R21: =-D21 -> 0
B22: Tarifa pacote Itaú | E22: -92.5
B23: IOF | E23: -196.01
B24: Pag Elektro (casa) | E24: -541.5
B25: Pag Elektro (posto) | D25: -235.18
B26: Transf. Lucila Regina Ceregato Correa | D26: -9300 | F26: =-D26 -> 9300 | AQ26: Saidas | AR26: #REF!
B27: Transf. Lucila Regina Ceregato Correa | D27: =-F27 -> 50749.16 | F27: -50749.16 | AQ27: Saidas | AR27: #REF!
B28: Pix Petroriente | D28: -50000
B29: Estorno mensalidade POS | D29: 420
B30: Tarifa TED envio Petroriente | D30: -4.9
AP31: =#REF! -> #REF!
B32: Venda de Gasolina | J32: =-M32 -> 7683.33 | K32: -1327 | L32: 5.79 | M32: =K32*L32 -> -7683.33 | AP32: =#REF! -> #REF!
B33: Venda de Etanol | J33: =-P33 -> 8876.18 | N33: -2342 | O33: 3.79 | P33: =N33*O33 -> -8876.18 | AP33: =#REF! -> #REF!
B34: Separação Cartão/Outros | H34: =-J34-I34 -> 5921.58 | I34: 10637.93 | J34: =-SUM(J32:J33) -> -16559.51 | AP34: =#REF! -> #REF!
B35: Ajuste estoque e valor diário (lucro embutido) | K35: 133 | M35: =(K38*L18)-M18-M32 -> 1740.8716 | N35: -3 | P35: =(N38*O18)-P18-P33 -> 560.48448 | AP35: =#REF! -> #REF!
AO36: =A19 -> 45932 | AP36: =#REF! -> #REF!
B37: Saldo Giro no dia | C37: =D38+E38+F38+G38+H38+I38+J38+M38+P38 -> 56926.47 | AO37: =SUM($Q18:AN37) -> -420377.88 | AS37: TERCEIROS
B38: Saldo Líquido do dia | C38: =AO38 -> -363451.41 | D38: =SUM(D18:D37) -> 1026.96 | E38: =SUM(E18:E37) -> -22070.31 | F38: =SUM(F18:F37) -> 0 | G38: =SUM(G18:G37) -> 0 | H38: =SUM(H18:H37) -> 3016.23 | I38: =SUM(I18:I37) -> 10637.93 | J38: =SUM(J18:J37) -> 0 | K38: =SUM(K18:K37) -> 2706 | L38: =M38/K38 -> 4.9769327 | M38: =ROUND(SUM(M18:M37),2) -> 13467.58 | N38: =SUM(N18:N37) -> 14339 | O38: =P38/N38 -> 3.5461385 | P38: =ROUND(SUM(P18:P37),2) -> 50848.08 | Q38: =SUM(Q18:Q37) -> -248820 | R38: =SUM(R18:R37) -> 7865.57 | S38: =SUM(S18:S37) -> 0 | T38: =SUM(T18:T37) -> -16073.45 | U38: =SUM(U18:U37) -> 0 | V38: =SUM(V18:V37) -> -163350 | W38: =SUM(W18:W37) -> 0 | X38: =SUM(X18:X37) -> 0 | ... AN38: =SUM(AN18:AN37) -> 0 | AO38: =D38+E38+F38+G38+H38+I38+J38+M38+P38+SUM(Q38:AN38) -> -363451.41 | AS38: SALDO C/C
A39: =A19+1 -> 45933 | B39: Credito Vendas Cartão | D39: 10378.19 | I39: =-D39 -> -10378.19
B40: Desconto taxas Cartão | I40: =-I38-I39 -> -259.74
...

Sheet Nov25
A1: PERÍODO 01 á 30/NOV/25 | C1: =D2+E2+F2+G2+H2+I2+J2+M2+P2 -> 135970.47 | D1: SPOT | E1: ITAU | F1: LUCILA | G1: HADEN | H1: CAIXA | I1: CARTAO | J1: VENDAS | K1: GASOLINA | N1: ETANOL | Q1: ERALDO | R1: LUIZ F. | S1: LUCILA | T1: DIVIDA | U1: AVANT | V1: WL | AO1: Total | AP1: Saldo Total | AQ1: Saldo Edson | AR1: Saldo Master
B2: Saldo Inicial do dia | C2: =D2+E2+F2+G2+H2+I2+J2+M2+P2+SUM(Q2:AN2) -> -310071.44 | D2: ='Out25'!D486 -> 9194.857 | E2: ='Out25'!E486 -> -22339.08 | F2: ='Out25'!F486 -> 0 | G2: ='Out25'!G486 -> 0 | H2: ='Out25'!H486 -> 9400 | I2: ='Out25'!I486 -> 11823.73 | J2: ='Out25'!J486 -> 0 | K2: ='Out25'!K486 -> 12517 | ... AO2: ='Out25'!AO486 -> -310071.44 | AP2: =#REF! -> #REF! | AQ2: =#REF! -> #REF! | AR2: =AP2-AQ2 -> #REF!
A3: 45962 | B3: Credito Vendas Cartão | D3: 11540.89 | I3: =-D3 -> -11540.89 | AQ3: Saidas | AR3: #REF!
B4: Desconto taxas Cartão | I4: =-I2-I3 -> -282.84 | AQ4: Saidas | AR4: #REF!
B5: Mensalidade POS | D5: -70 | AQ5: Saidas | AR5: #REF!
B6: Pix e depósitos Banco Itaú | AQ6: Saidas | AR6: #REF!
B7: Transf. Lucila Regina Ceregato Correa | D7: -20600 | F7: =-D7 -> 20600 | AQ7: Saidas | AR7: #REF!
AP8: =#REF! -> #REF!
B9: Venda de Gasolina | J9: =-M9 -> 6171.75 | K9: -1055 | L9: 5.85 | M9: =K9*L9 -> -6171.75 | AP9: =#REF! -> #REF!
B10: Venda de Etanol | J10: =-P10 -> 9365.09 | N10: -2471 | O10: 3.79 | P10: =N10*O10 -> -9365.09 | AP10: =#REF! -> #REF!
B11: Separação Cartão/Outros | H11: =-J11-I11 -> 5287.86 | I11: 10248.98 | J11: =-SUM(J9:J10) -> -15536.84 | AO11: =A2 -> 0 | AP11: =#REF! -> #REF!
B12: Ajuste estoque e valor diário (lucro embutido) | K12: -159 | M12: =(K15*((M2)/(K2))-M2-M9) -> 54.018278 | N12: -126 | P12: =(N15*((P2)/(N2))-P2-P10) -> 292.13342 | AP12: =#REF! -> #REF!
AO13: =A3 -> 45962 | AP13: =#REF! -> #REF!
B14: Saldo Giro no dia | C14: =D15+E15+F15+G15+H15+I15+J15+M15+P15 -> 135963.78 | M14: =K14*L14 -> 0 | P14: =N14*O14 -> 0 | AO14: =SUM($Q2:AN14) -> -446041.91 | AS14: TERCEIROS
B15: Saldo Líquido do dia | C15: =AO15 -> -310078.13 | D15: =SUM(D2:D14) -> 65.74704 | E15: =SUM(E2:E14) -> -22339.08 | F15: =SUM(F2:F14) -> 20600 | G15: =SUM(G2:G14) -> 0 | H15: =SUM(H2:H14) -> 14687.86 | I15: =SUM(I2:I14) -> 10248.98 | J15: =SUM(J2:J14) -> 0 | K15: =SUM(K2:K14) -> 11303 | L15: =M15/K15 -> 5.0393179 | M15: =ROUND(SUM(M2:M14),2) -> 56959.41 | N15: =SUM(N2:N14) -> 15955 | O15: =P15/N15 -> 3.4936296 | P15: =ROUND(SUM(P2:P14),2) -> 55740.86 | Q15: =SUM(Q2:Q14) -> -423778.33 | R15: =SUM(R2:R14) -> 37928.52 | S15: =SUM(S2:S14) -> 0 | T15: =SUM(T2:T14) -> -12858.76 | U15: =SUM(U2:U14) -> -35100 | V15: =SUM(V2:V14) -> -12233.34 | W15: =SUM(W2:W14) -> 0 | X15: =SUM(X2:X14) -> 0 | ... AH15: =SUM(AH2:AH14) -> 0 | AJ15: =SUM(AJ2:AJ14) -> 0 | AK15: =SUM(AK2:AK14) -> 0 | AL15: =SUM(AL2:AL14) -> 0 | AM15: =SUM(AM2:AM14) -> 0 | AN15: =SUM(AN2:AN14) -> 0 | AO15: =D15+E15+F15+G15+H15+I15+J15+M15+P15+SUM(Q15:AN15) -> -310078.13 | AS15: SALDO C/C
A16: =A3+1 -> 45963 | B16: Credito Vendas Cartão | D16: 10001.27 | I16: =-D16 -> -10001.27 | AP16: =#REF! -> #REF!
B17: Desconto taxas Cartão | I17: =-I15-I16 -> -247.71
B18: Pix e depósitos Banco Itaú | R18: =-D18 -> 0
B19: Transf. Lucila Regina Ceregato Correa | D19: -10000 | F19: =-D19 -> 10000 | AQ19: Saidas | AR19: #REF!
AP20: =#REF! -> #REF!
B21: Venda de Gasolina | J21: =-M21 -> 5528.25 | K21: -945 | L21: 5.85 | M21: =K21*L21 -> -5528.25 | AP21: =#REF! -> #REF!
B22: Venda de Etanol | J22: =-P22 -> 5825.23 | N22: -1537 | O22: 3.79 | P22: =N22*O22 -> -5825.23 | AP22: =#REF! -> #REF!
B23: Separação Cartão/Outros | H23: =-J23-I23 -> 4815.04 | I23: 6538.44 | J23: =-SUM(J21:J22) -> -11353.48 | AP23: =#REF! -> #REF!
B24: Ajuste estoque e valor diário (lucro embutido) | K24: -26 | M24: =(K27*((M15)/(K15))-M15-M21) -> 635.07234 | N24: 82 | P24: =(N27*((P15)/(N15))-P15-P22) -> 741.99896 | AP24: =#REF! -> #REF!
AO25: =A16 -> 45963 | AP25: =#REF! -> #REF!
B26: Saldo Giro no dia | C26: =D27+E27+F27+G27+H27+I27+J27+M27+P27 -> 137093.14 | AO26: =SUM($Q15:AN26) -> -446041.91 | AS26: TERCEIROS
B27: Saldo Líquido do dia | C27: =AO27 -> -308948.77 | D27: =SUM(D15:D26) -> 67.01704 | E27: =SUM(E15:E26) -> -22339.08 | F27: =SUM(F15:F26) -> 30600 | G27: =SUM(G15:G26) -> 0 | H27: =SUM(H15:H26) -> 19502.9 | I27: =SUM(I15:I26) -> 6538.44 | J27: =SUM(J15:J26) -> 0 | K27: =SUM(K15:K26) -> 10332 | L27: =M27/K27 -> 5.0393177 | M27: =ROUND(SUM(M15:M26),2) -> 52066.23 | N27: =SUM(N15:N26) -> 14500 | O27: =P27/N27 -> 3.4936297 | P27: =ROUND(SUM(P15:P26),2) -> 50657.63 | Q27: =SUM(Q15:Q26) -> -423778.33 | R27: =SUM(R15:R26) -> 37928.52 | S27: =SUM(S15:S26) -> 0 | T27: =SUM(T15:T26) -> -12858.76 | U27: =SUM(U15:U26) -> -35100 | V27: =SUM(V15:V26) -> -12233.34 | W27: =SUM(W15:W26) -> 0 | X27: =SUM(X15:X26) -> 0 | ... AN27: =SUM(AN15:AN26) -> 0 | AO27: =D27+E27+F27+G27+H27+I27+J27+M27+P27+SUM(Q27:AN27) -> -308948.77 | AS27: SALDO C/C
A28: =A16+1 -> 45964 | B28: Credito Vendas Cartão | D28: 6358.67 | I28: =-D28 -> -6358.67
B29: Desconto taxas Cartão | I29: =-I27-I28 -> -179.77
B30: Transf. Lucila Regina Ceregato Correa | D30: -6400 | F30: =-D30 -> 6400 | AQ30: Saidas | AR30: #REF!
B31: Pix e depósitos Banco Itaú | E31: =-18952.16+64.89-E27 -> 3451.81 | H31: =-E31 -> -3451.81 | AQ31: Saidas | AR31: #REF!
B32: Conselho Regional | E32: -64.89
B33: Pag NF 109841 Avant 10x3,51 EH Venc 03/11 | F33: -35100 | U33: =-F33 -> 35100
B35: Venda de Gasolina | J35: =-M35 -> 7914.93 | K35: -1367 | L35: 5.79 | M35: =K35*L35 -> -7914.93 | AP35: =#REF! -> #REF!
B36: Venda de Etanol | J36: =-P36 -> 8273.57 | N36: -2183 | O36: 3.79 | P36: =N36*O36 -> -8273.57 | AP36: =#REF! -> #REF!
B37: Separação Cartão/Outros | H37: =-J37-I37 -> 5065.79 | I37: 11122.71 | J37: =-SUM(J35:J36) -> -16188.5 | AO37: =A18 -> 0 | AP37: =#REF! -> #REF!
B38: Ajuste de saldo e valor estoque diário | K38: 35 | M38: =(K41*((M27)/(K27))-M27-M35) -> 1202.5589 | N38: 3 | P38: =(N41*((P27)/(N27))-P27-P36) -> 657.45735 | AO38: =A17 -> 0 | AP38: =#REF! -> #REF!
B40: Saldo Giro no dia | C40: =D41+E41+F41+G41+H41+I41+J41+M41+P41 -> 103608.5 | AO40: =SUM($Q27:AN40) -> -410941.91 | AS40: TERCEIROS
B41: Saldo Líquido do dia | C41: =AO41 -> -307333.41 | D41: =SUM(D27:D40) -> 25.68704 | E41: =SUM(E27:E40) -> -18952.16 | F41: =SUM(F27:F40) -> 1900 | G41: =SUM(G27:G40) -> 0 | H41: =SUM(H27:H40) -> 21116.88 | I41: =SUM(I27:I40) -> 11122.71 | J41: =SUM(J27:J40) -> 0 | K41: =SUM(K27:K40) -> 9000 | L41: =M41/K41 -> 5.0393178 | M41: =ROUND(SUM(M27:M40),2) -> 45353.86 | N41: =SUM(N27:N40) -> 12320 | O41: =P41/N41 -> 3.4936299 | P41: =ROUND(SUM(P27:P40),2) -> 43041.52 | Q41: =SUM(Q27:Q40) -> -423778.33 | R41: =SUM(R27:R40) -> 37928.52 | S41: =SUM(S27:S40) -> 0 | T41: =SUM(T27:T40) -> -12858.76 | U41: =SUM(U27:U40) -> 0 | V41: =SUM(V27:V40) -> -12233.34 | W41: =SUM(W27:W40) -> 0 | X41: =SUM(X27:X40) -> 0 | ... AN41: =SUM(AN27:AN40) -> 0 | AO41: =D41+E41+F41+G41+H41+I41+J41+M41+P41+SUM(Q41:AN41) -> -307333.41 | AS41: SALDO C/C
A42: =A28+1 -> 45965 | B42: Credito Vendas Cartão | D42: 10857.77 | I42: =-D42 -> -10857.77
...

Sheet Dez25
A1: PERÍODO 01 á 31/DEZ/25 | C1: =D2+E2+F2+G2+H2+I2+J2+M2+P2 -> 119457.56 | D1: SPOT | E1: ITAU | F1: LUCILA | G1: HADEN | H1: CAIXA | I1: CARTAO | J1: VENDAS | K1: GASOLINA | N1: ETANOL | Q1: ERALDO | R1: LUIZ F. | S1: LUCILA | T1: DIVIDA | U1: AVANT | V1: WL | AO1: Total | AP1: Saldo Total | AQ1: Saldo Edson | AR1: Saldo Master
B2: Saldo Inicial do dia | C2: =D2+E2+F2+G2+H2+I2+J2+M2+P2+SUM(Q2:AN2) -> -303063.44 | D2: ='Nov25'!D443 -> 23.65704 | E2: ='Nov25'!E443 -> -19624.86 | F2: ='Nov25'!F443 -> 26680 | G2: ='Nov25'!G443 -> 0 | H2: ='Nov25'!H443 -> 48361.543 | I2: ='Nov25'!I443 -> 8718.39 | J2: ='Nov25'!J443 -> 0 | K2: ='Nov25'!K443 -> 6757 | ... AO2: ='Nov25'!AO443 -> -303063.44 | AP2: =#REF! -> #REF! | AQ2: =#REF! -> #REF! | AR2: =AP2-AQ2 -> #REF!
A3: 45992 | B3: Credito Vendas Cartão | D3: 8509.07 | I3: =-D3 -> -8509.07 | AQ3: Saidas | AR3: #REF!
B4: Desconto taxas Cartão | I4: =-I2-I3 -> -209.32 | AQ4: Saidas | AR4: #REF!
B5: Transf. Lucila Regina Ceregato Correa | D5: -8500 | F5: =-D5 -> 8500 | AQ5: Saidas | AR5: #REF!
B6: Transf. Itau p/ Spotbank | D6: 1300 | E6: =-D6 -> -1300 | AQ6: Saidas | AR6: #REF!
B7: Tarifa recebimento pix | D7: -10.4 | AQ7: Saidas | AR7: #REF!
B8: Transf. Lucila Regina Ceregato Correa | D8: 35180 | F8: =-D8 -> -35180 | AQ8: Saidas | AR8: #REF!
B9: Pag NF 98565 Petroriente 10x3,63 EH | D9: -36300 | V9: =-D9 -> 36300
B10: Pix e depósitos Banco Itaú | E10: =-E2+1300-10141.86+550.81 -> 11333.81 | H10: =-E10 -> -11333.81 | AQ10: Saidas | AR10: #REF!
B11: Pag DARF | E11: -550.81
AQ12: Saidas | AR12: #REF!
AP13: =#REF! -> #REF!
B14: Venda de Gasolina | J14: =-M14 -> 8862.75 | K14: -1515 | L14: 5.85 | M14: =K14*L14 -> -8862.75 | AP14: =#REF! -> #REF!
B15: Venda de Etanol | J15: =-P15 -> 9692.89 | N15: -2479 | O15: 3.91 | P15: =N15*O15 -> -9692.89 | AP15: =#REF! -> #REF!
B16: Separação Cartão/Outros | H16: =-J16-I16 -> 6933.26 | I16: 11622.38 | J16: =-SUM(J14:J15) -> -18555.64 | AO16: =A2 -> 0 | AP16: =#REF! -> #REF!
B17: Ajuste estoque e valor diário (lucro embutido) | K17: 47 | M17: =(K20*L2)-M2-M14 -> 1460.5474 | N17: 80 | P17: =(N20*((P2)/(N2))-P2-P15) -> 1046.9103 | AP17: =#REF! -> #REF!
AO18: =A3 -> 45992 | AP18: =#REF! -> #REF!
B19: Saldo Giro no dia | C19: =D20+E20+F20+G20+H20+I20+J20+M20+P20 -> 84894.49 | M19: =K19*L19 -> 0 | P19: =N19*O19 -> 0 | AO19: =SUM($Q2:AN19) -> -386221 | AS19: TERCEIROS
B20: Saldo Líquido do dia | C20: =AO20 -> -301326.51 | D20: =SUM(D2:D19) -> 202.32704 | E20: =SUM(E2:E19) -> -10141.86 | F20: =SUM(F2:F19) -> 0 | G20: =SUM(G2:G19) -> 0 | H20: =SUM(H2:H19) -> 43960.993 | I20: =SUM(I2:I19) -> 11622.38 | J20: =SUM(J2:J19) -> 0 | K20: =SUM(K2:K19) -> 5289 | L20: =M20/K20 -> 5.0423728 | M20: =ROUND(SUM(M2:M19),2) -> 26669.11 | N20: =SUM(N2:N19) -> 3491 | O20: =P20/N20 -> 3.6039931 | P20: =ROUND(SUM(P2:P19),2) -> 12581.54 | Q20: =SUM(Q2:Q19) -> -426806.23 | R20: =SUM(R2:R19) -> 50229.3 | S20: =SUM(S2:S19) -> 0 | T20: =SUM(T2:T19) -> -9644.07 | U20: =SUM(U2:U19) -> 0 | V20: =SUM(V2:V19) -> 0 | W20: =SUM(W2:W19) -> 0 | X20: =SUM(X2:X19) -> 0 | ... AH20: =SUM(AH2:AH19) -> 0 | AJ20: =SUM(AJ2:AJ19) -> 0 | AK20: =SUM(AK2:AK19) -> 0 | AL20: =SUM(AL2:AL19) -> 0 | AM20: =SUM(AM2:AM19) -> 0 | AN20: =SUM(AN2:AN19) -> 0 | AO20: =D20+E20+F20+G20+H20+I20+J20+M20+P20+SUM(Q20:AN20) -> -301326.51 | AS20: SALDO C/C
A21: =A3+1 -> 45993 | B21: Credito Vendas Cartão | D21: 11328.94 | I21: =-D21 -> -11328.94 | AP21: =#REF! -> #REF!
B22: Desconto taxas Cartão | I22: =-I20-I21 -> -293.44
B23: Pix e depósitos Banco Itaú | E23: =-E20-8223.89+92.5+232.01+388.81+244.4+1671 -> 4546.69 | H23: =-E23 -> -4546.69 | R23: =-D23 -> 0
B24: Tarifa pacote | E24: -92.5
B25: IOF | E25: -232.01
B26: Pag Elektro (casa)
B27: Pag Juliano Araujo | D27: -488
B28: Tarifa pix Juliano Araujo | D28: -4.9 | AQ28: Saidas | AR28: #REF!
B29: Pag DAAE | E29: -388.81
B30: Pag Elektro | E30: -244.4
B31: Transf. p/ Eraldo | E31: -1671 | Q31: =-E31 -> 1671
AP34: =#REF! -> #REF!
B35: Venda de Gasolina | J35: =-M35 -> 7610.85 | K35: -1301 | L35: 5.85 | M35: =K35*L35 -> -7610.85 | AP35: =#REF! -> #REF!
B36: Venda de Etanol | J36: =-P36 -> 7260.87 | N36: -1857 | O36: 3.91 | P36: =N36*O36 -> -7260.87 | AP36: =#REF! -> #REF!
B37: Separação Cartão/Outros | H37: =-J37-I37 -> 4787.27 | I37: 10084.45 | J37: =-SUM(J35:J36) -> -14871.72 | AP37: =#REF! -> #REF!
B38: Ajuste estoque e valor diário (lucro embutido) | K38: 4 | M38: =(K41*L20)-M20-M35 -> 1070.8924 | N38: 140 | P38: =(N41*O20)-P20-P36 -> 1072.8138 | AP38: =#REF! -> #REF!
AO39: =A21 -> 45993 | AP39: =#REF! -> #REF!
B40: Saldo Giro no dia | C40: =D41+E41+F41+G41+H41+I41+J41+M41+P41 -> 83623.13 | AO40: =SUM($Q20:AN40) -> -384550 | AS40: TERCEIROS
B41: Saldo Líquido do dia | C41: =AO41 -> -300926.87 | D41: =SUM(D20:D40) -> 11038.367 | E41: =SUM(E20:E40) -> -8223.89 | F41: =SUM(F20:F40) -> 0 | G41: =SUM(G20:G40) -> 0 | H41: =SUM(H20:H40) -> 44201.573 | I41: =SUM(I20:I40) -> 10084.45 | J41: =SUM(J20:J40) -> 0 | K41: =SUM(K20:K40) -> 3992 | L41: =M41/K41 -> 5.0423722 | M41: =ROUND(SUM(M20:M40),2) -> 20129.15 | N41: =SUM(N20:N40) -> 1774 | O41: =P41/N41 -> 3.603991 | P41: =ROUND(SUM(P20:P40),2) -> 6393.48 | Q41: =SUM(Q20:Q40) -> -425135.23 | R41: =SUM(R20:R40) -> 50229.3 | S41: =SUM(S20:S40) -> 0 | T41: =SUM(T20:T40) -> -9644.07 | U41: =SUM(U20:U40) -> 0 | V41: =SUM(V20:V40) -> 0 | W41: =SUM(W20:W40) -> 0 | X41: =SUM(X20:X40) -> 0 | ... AN41: =SUM(AN20:AN40) -> 0 | AO41: =D41+E41+F41+G41+H41+I41+J41+M41+P41+SUM(Q41:AN41) -> -300926.87 | AS41: SALDO C/C
A42: =A21+1 -> 45994 | B42: Credito Vendas Cartão | D42: 9833.36 | I42: =-D42 -> -9833.36
...

Sheet Jan26
A1: PERÍODO 01 á 31/JAN/26 | C1: =D2+E2+F2+G2+H2+I2+J2+M2+P2 -> 153061.83 | D1: SPOT | E1: ITAU | F1: LUCILA | G1: HADEN | H1: CAIXA | I1: CARTAO | J1: VENDAS | K1: GASOLINA | N1: ETANOL | Q1: ERALDO | R1: LUIZ F. | S1: LUCILA | T1: DIVIDA | U1: AVANT | V1: WL | AO1: Total | AP1: Saldo Total | AQ1: Saldo Edson | AR1: Saldo Master
B2: Saldo Inicial do dia | C2: =D2+E2+F2+G2+H2+I2+J2+M2+P2+SUM(Q2:AN2) -> -333323.48 | D2: ='Dez25'!D454 -> 6322.387 | E2: ='Dez25'!E454 -> -31610.26 | F2: ='Dez25'!F454 -> 0.5 | G2: ='Dez25'!G454 -> 0 | H2: ='Dez25'!H454 -> 60399.273 | I2: ='Dez25'!I454 -> 34519.82 | J2: ='Dez25'!J454 -> 0 | K2: ='Dez25'!K454 -> 6152 | ... AO2: ='Dez25'!AO454 -> -333323.48 | AP2: =#REF! -> #REF! | AQ2: =#REF! -> #REF! | AR2: =AP2-AQ2 -> #REF!
A3: 46023 | B3: Credito Vendas Cartão | AQ3: Saidas | AR3: #REF!
B4: Desconto taxas Cartão | AQ4: Saidas | AR4: #REF!
B5: Mensalidade POS | AQ5: Saidas | AR5: #REF!
B6: Pix e depósitos Banco Itaú | AQ6: Saidas | AR6: #REF!
B7: Pix e depósitos Banco Itaú - Lucila
B8: Transf. Lucila | AQ8: Saidas | AR8: #REF!
B9: Transf. Lucila Regina Ceregato Correa | AQ9: Saidas | AR9: #REF!
AP10: =#REF! -> #REF!
B11: Venda de Gasolina | J11: =-M11 -> 3082.1 | K11: -518 | L11: 5.95 | M11: =K11*L11 -> -3082.1 | AP11: =#REF! -> #REF!
B12: Venda de Etanol | J12: =-P12 -> 5599.86 | N12: -1407 | O12: 3.98 | P12: =N12*O12 -> -5599.86 | AP12: =#REF! -> #REF!
B13: Separação Cartão/Outros | H13: =-J13-I13 -> 3006.64 | I13: 5675.32 | J13: =-SUM(J11:J12) -> -8681.96 | AO13: =A2 -> 0 | AP13: =#REF! -> #REF!
B14: Ajuste estoque e valor diário (lucro embutido) | K14: -52 | M14: =(K17*M2/K2)-M2-M11 -> 183.82141 | N14: 9 | P14: =(N17*((P2)/(N2))-P2-P12) -> 402.42948 | AP14: =#REF! -> #REF!
AO15: =A3 -> 46023 | AP15: =#REF! -> #REF!
B16: Saldo Giro no dia | C16: =D17+E17+F17+G17+H17+I17+J17+M17+P17 -> 153648.08 | M16: =K16*L16 -> 0 | P16: =N16*O16 -> 0 | AO16: =SUM($Q2:AN16) -> -486385.31 | AS16: TERCEIROS
B17: Saldo Líquido do dia | C17: =AO17 -> -332737.23 | D17: =SUM(D2:D16) -> 6322.387 | E17: =SUM(E2:E16) -> -31610.26 | F17: =SUM(F2:F16) -> 0.5 | G17: =SUM(G2:G16) -> 0 | H17: =SUM(H2:H16) -> 63405.913 | I17: =SUM(I2:I16) -> 40195.14 | J17: =SUM(J2:J16) -> 0 | K17: =SUM(K2:K16) -> 5582 | L17: =M17/K17 -> 5.084699 | M17: =ROUND(SUM(M2:M16),2) -> 28382.79 | N17: =SUM(N2:N16) -> 12629 | O17: =P17/N17 -> 3.7177615 | P17: =ROUND(SUM(P2:P16),2) -> 46951.61 | Q17: =SUM(Q2:Q16) -> -530185.23 | R17: =SUM(R2:R16) -> 50229.3 | S17: =SUM(S2:S16) -> 0 | T17: =SUM(T2:T16) -> -6429.38 | U17: =SUM(U2:U16) -> 0 | V17: =SUM(V2:V16) -> 0 | W17: =SUM(W2:W16) -> 0 | X17: =SUM(X2:X16) -> 0 | ... AH17: =SUM(AH2:AH16) -> 0 | AJ17: =SUM(AJ2:AJ16) -> 0 | AK17: =SUM(AK2:AK16) -> 0 | AL17: =SUM(AL2:AL16) -> 0 | AM17: =SUM(AM2:AM16) -> 0 | AN17: =SUM(AN2:AN16) -> 0 | AO17: =D17+E17+F17+G17+H17+I17+J17+M17+P17+SUM(Q17:AN17) -> -332737.23 | AS17: SALDO C/C
A18: =A3+1 -> 46024 | B18: Credito Vendas Cartão 29/12/25 | D18: 9957.83 | I18: =-D18 -> -9957.83 | AP18: =#REF! -> #REF!
B19: Desconto taxas Cartão | I19: =D18-10212.14 -> -254.31
B20: Credito Vendas Cartão 30/12/25 | D20: 11108.16 | I20: =-D20 -> -11108.16 | AP20: =#REF! -> #REF!
B21: Desconto taxas Cartão | I21: =D20-11357.12 -> -248.96
B22: Credito Vendas Cartão 31/12/25 | D22: 12664.08 | I22: =-D22 -> -12664.08 | AP22: =#REF! -> #REF!
B23: Desconto taxas Cartão | I23: =D22-12950.56 -> -286.48
B24: Credito Vendas Cartão 01/01/26 | D24: 5554.6 | I24: =-D24 -> -5554.6 | AP24: =#REF! -> #REF!
B25: Desconto taxas Cartão | I25: =D24-5675.32 -> -120.72
B26: Pix e depósitos Banco Itaú | E26: =80+50+100+13+100+50+100+5+55+50+30+25+80+80+30+50+110+160+20+30+20+100+23+150+13+320+50+50+20+70+100+30+200+25+40+100+59.5+50+70+60+10+30+50 -> 2858.5 | H26: =-E26 -> -2858.5 | R26: =-D26 -> 0
B27: Tarifa pacote Itaú
B28: IOF
B29: Pag Elektro (casa)
B30: Pag Elektro (posto)
B31: Transf. Lucila Regina Ceregato Correa | D31: -45600 | F31: =-D31 -> 45600 | AQ31: Saidas | AR31: #REF!
B32: Pix Petroriente
B33: Estorno mensalidade POS
B34: Tarifa TED envio Petroriente
AP35: =#REF! -> #REF!
B36: Venda de Gasolina | J36: =-M36 -> 5825.05 | K36: -979 | L36: 5.95 | M36: =K36*L36 -> -5825.05 | AP36: =#REF! -> #REF!
B37: Venda de Etanol | J37: =-P37 -> 5046.64 | N37: -1268 | O37: 3.98 | P37: =N37*O37 -> -5046.64 | AP37: =#REF! -> #REF!
B38: Separação Cartão/Outros | H38: =-J38-I38 -> 3430.45 | I38: 7441.24 | J38: =-SUM(J36:J37) -> -10871.69 | AP38: =#REF! -> #REF!
B39: Ajuste estoque e valor diário (lucro embutido) | K39: 39 | M39: =(K42*M17/K17)-M17-M36 -> 1045.4329 | N39: -115 | P39: =(N42*P17/N17)-P17-P37 -> -95.024156 | AP39: =#REF! -> #REF!
AO40: =A18 -> 46024 | AP40: =#REF! -> #REF!
...

Sheet Fev26
A1: PERÍODO 01 á 28/FEV/26 | C1: =D2+E2+F2+G2+H2+I2+J2+M2+P2 -> 212030.33 | D1: SPOT | E1: ITAU | F1: LUCILA | G1: HADEN | H1: CAIXA | I1: CARTAO | J1: VENDAS | K1: GASOLINA | N1: ETANOL | Q1: ERALDO | R1: LUIZ F. | S1: LUCILA | T1: DIVIDA | U1: AVANT | V1: WL | AO1: Total | AP1: Saldo Total | AQ1: Saldo Edson | AR1: Saldo Master
B2: Saldo Inicial do dia | C2: =D2+E2+F2+G2+H2+I2+J2+M2+P2+SUM(Q2:AN2) -> -355912.19 | D2: ='Jan26'!D578 -> 21384.817 | E2: ='Jan26'!E578 -> -22447.41 | F2: ='Jan26'!F578 -> 28395.65 | G2: ='Jan26'!G578 -> 0 | H2: ='Jan26'!H578 -> 66257.343 | I2: ='Jan26'!I578 -> 8772.28 | J2: ='Jan26'!J578 -> 0 | K2: ='Jan26'!K578 -> 2000 | ... AO2: ='Jan26'!AO578 -> -355912.19 | AP2: =#REF! -> #REF! | AQ2: =#REF! -> #REF! | AR2: =AP2-AQ2 -> #REF!
A3: 46054 | B3: Credito Vendas Cartão | D3: 8574.06 | I3: =-D3 -> -8574.06 | AQ3: Saidas | AR3: #REF!
B4: Desconto taxas Cartão | I4: =-I2-I3 -> -198.22 | AQ4: Saidas | AR4: #REF!
B5: Pix recebido maquininha | D5: =50+30+40+50+50+120+30+20+50.4+100+30+50+73 -> 693.4 | I5: =-D5 -> -693.4
B6: Tarifa pix recebido maquinha | D6: =-13*0.99 -> -12.87
AP7: =#REF! -> #REF!
B8: Venda de Gasolina | J8: =-M8 -> 5872.65 | K8: -987 | L8: 5.95 | M8: =K8*L8 -> -5872.65 | AP8: =#REF! -> #REF!
B9: Venda de Etanol | J9: =-P9 -> 6772.8 | N9: -1660 | O9: 4.08 | P9: =N9*O9 -> -6772.8 | AP9: =#REF! -> #REF!
B10: Separação Cartão/Outros | H10: =-J10-I10 -> 4740.78 | I10: 7904.67 | J10: =-SUM(J8:J9) -> -12645.45 | AO10: =A2 -> 0 | AP10: =#REF! -> #REF!
B11: Ajuste estoque e valor diário (lucro embutido) | K11: 36 | M11: =(K14*M2/K2)-M2-M8 -> 872.99099 | N11: -193 | P11: =(N14*((P2)/(N2))-P2-P9) -> -239.82333 | AP11: =#REF! -> #REF!
AO12: =A3 -> 46054 | AP12: =#REF! -> #REF!
B13: Saldo Giro no dia | C13: =D14+E14+F14+G14+H14+I14+J14+M14+P14 -> 212452.41 | M13: =K13*L13 -> 0 | P13: =N13*O13 -> 0 | AO13: =SUM($Q2:AN13) -> -567942.52 | AS13: TERCEIROS
B14: Saldo Líquido do dia | C14: =AO14 -> -355490.11 | D14: =SUM(D2:D13) -> 30639.407 | E14: =SUM(E2:E13) -> -22447.41 | F14: =SUM(F2:F13) -> 28395.65 | G14: =SUM(G2:G13) -> 0 | H14: =SUM(H2:H13) -> 70998.123 | I14: =SUM(I2:I13) -> 7211.27 | J14: =SUM(J2:J13) -> 0 | K14: =SUM(K2:K13) -> 1049 | L14: =M14/K14 -> 5.2572641 | M14: =ROUND(SUM(M2:M13),2) -> 5514.87 | N14: =SUM(N2:N13) -> 24347 | O14: =P14/N14 -> 3.7844704 | P14: =ROUND(SUM(P2:P13),2) -> 92140.5 | Q14: =SUM(Q2:Q13) -> -614957.13 | R14: =SUM(R2:R13) -> 50229.3 | S14: =SUM(S2:S13) -> 0 | T14: =SUM(T2:T13) -> -3214.69 | U14: =SUM(U2:U13) -> 0 | V14: =SUM(V2:V13) -> 0 | W14: =SUM(W2:W13) -> 0 | X14: =SUM(X2:X13) -> 0 | ... AH14: =SUM(AH2:AH13) -> 0 | AJ14: =SUM(AJ2:AJ13) -> 0 | AK14: =SUM(AK2:AK13) -> 0 | AL14: =SUM(AL2:AL13) -> 0 | AM14: =SUM(AM2:AM13) -> 0 | AN14: =SUM(AN2:AN13) -> 0 | AO14: =D14+E14+F14+G14+H14+I14+J14+M14+P14+SUM(Q14:AN14) -> -355490.11 | AS14: SALDO C/C
A15: =A3+1 -> 46055 | B15: Credito Vendas Cartão | D15: 7034.51 | I15: =-D15 -> -7034.51 | AP15: =#REF! -> #REF!
B16: Desconto taxas Cartão | I16: =-I14-I15 -> -176.76 | AP16: =#REF! -> #REF!
B17: Pix recebido maquininha | D17: =172+50+50+100+50+100+50+100+50+51.6+80+100 -> 953.6 | I17: =-D17 -> -953.6 | AP17: =#REF! -> #REF!
B18: Tarifa pix recebido maquinha | D18: =-11*0.99-1.38 -> -12.27 | AP18: =#REF! -> #REF!
B19: Transf. Lucila | D19: 28395 | F19: =-D19 -> -28395
B20: Pix e depósitos Banco Itaú | E20: =70+100+15+70+50+50+20+34+70+15+50+179+50+50+30+50+30+21+100+20+327+100+1130+1935+120+928+1168+752+1380+60 -> 8974 | H20: =-E20 -> -8974 | R20: =-D20 -> 0
B21: Pag Linx | E21: -184.86
B22: Pag Nexta NF 10705 | D22: -25575 | K22: 5000 | L22: 5.115 | M22: =K22*L22 -> 25575
B23: Pag Nexta NF 10706 | D23: -25575 | K23: 5000 | L23: 5.115 | M23: =K23*L23 -> 25575
B24: Tarifa pix enviado | D24: =-4.9-4.9 -> -9.8
AP25: =#REF! -> #REF!
B26: Venda de Gasolina | J26: =-M26 -> 7508.9 | K26: -1262 | L26: 5.95 | M26: =K26*L26 -> -7508.9 | AP26: =#REF! -> #REF!
B27: Venda de Etanol | J27: =-P27 -> 7433.76 | N27: -1822 | O27: 4.08 | P27: =N27*O27 -> -7433.76 | AP27: =#REF! -> #REF!
B28: Separação Cartão/Outros | H28: =-J28-I28 -> 4494.91 | I28: 10447.75 | J28: =-SUM(J26:J27) -> -14942.66 | AP28: =#REF! -> #REF!
B29: Ajuste estoque e valor diário (lucro embutido) | K29: 148 | M29: =(K32*(M14+M22+M23)/(K14+K22+K23))-M14-M26-M22-M23 -> 1795.7436 | N29: -40 | P29: =(N32*P14/N14)-P14-P27 -> 387.07618 | AP29: =#REF! -> #REF!
AO30: =A15 -> 46055 | AP30: =#REF! -> #REF!
B31: Saldo Giro no dia | C31: =D32+E32+F32+G32+H32+I32+J32+M32+P32 -> 214251.54 | AO31: =SUM($Q14:AN31) -> -567942.52 | AS31: TERCEIROS
B32: Saldo Líquido do dia | C32: =AO32 -> -353690.98 | D32: =SUM(D14:D31) -> 15850.447 | E32: =SUM(E14:E31) -> -13658.27 | F32: =SUM(F14:F31) -> 0.65 | G32: =SUM(G14:G31) -> 0 | H32: =SUM(H14:H31) -> 66519.033 | I32: =SUM(I14:I31) -> 9494.15 | J32: =SUM(J14:J31) -> 0 | K32: =SUM(K14:K31) -> 9935 | L32: =M32/K32 -> 5.1285063 | M32: =ROUND(SUM(M14:M31),2) -> 50951.71 | N32: =SUM(N14:N31) -> 22485 | O32: =P32/N32 -> 3.7844705 | P32: =ROUND(SUM(P14:P31),2) -> 85093.82 | Q32: =SUM(Q14:Q31) -> -614957.13 | R32: =SUM(R14:R31) -> 50229.3 | S32: =SUM(S14:S31) -> 0 | T32: =SUM(T14:T31) -> -3214.69 | U32: =SUM(U14:U31) -> 0 | V32: =SUM(V14:V31) -> 0 | W32: =SUM(W14:W31) -> 0 | X32: =SUM(X14:X31) -> 0 | ... AN32: =SUM(AN14:AN31) -> 0 | AO32: =D32+E32+F32+G32+H32+I32+J32+M32+P32+SUM(Q32:AN32) -> -353690.98 | AS32: SALDO C/C
A33: =A15+1 -> 46056 | B33: Credito Vendas Cartão | D33: 9494.15 | I33: =-D33 -> -9494.15
B34: Desconto taxas Cartão | I34: =-I32-I33 -> 0
B35: Pix recebido maquininha | D35: =50+15+9+30+20+50+40+30+20+31+20+50+100+25+13.48 -> 503.48 | I35: =-D35 -> -503.48
B36: Tarifa pix recebido maquinha | D36: =-15*0.99 -> -14.85
B37: Transf. Eraldo | D37: -25300 | Q37: =-D37 -> 25300
B38: Tarifa pix enviado | D38: -4.9
B39: Pix e depósitos Banco Itaú | E39: =125+100+70+60+50+80+70 -> 555 | H39: =-E39 -> -555 | R39: =-D39 -> 0
B40: Transf. Locaste | E40: -76
...

Sheet Mar26
A1: PERÍODO 01 á 31/MAR/26 | C1: =D2+E2+F2+G2+H2+I2+J2+M2+P2 -> 117279.93 | D1: SPOT | E1: ITAU | F1: LUCILA | G1: HADEN | H1: CAIXA | I1: CARTAO | J1: VENDAS | K1: GASOLINA | N1: ETANOL | Q1: DIESEL | T1: ERALDO | U1: LUIZ F. | V1: LUCILA | W1: DIVIDA | X1: AVANT | Y1: WL | AR1: Total | AS1: Saldo Total | AT1: Saldo Edson | AU1: Saldo Master
B2: Saldo Inicial do dia | C2: =D2+E2+F2+G2+H2+I2+J2+M2+P2+SUM(T2:AQ2) -> -369807.9 | D2: ='Fev26'!D469 -> 12717.607 | E2: ='Fev26'!E469 -> -43287.79 | F2: ='Fev26'!F469 -> 0.65 | G2: ='Fev26'!G469 -> 0 | H2: ='Fev26'!H469 -> 65082.293 | I2: ='Fev26'!I469 -> 10004.65 | J2: ='Fev26'!J469 -> 0 | K2: ='Fev26'!K469 -> 12170 | ... P2: ='Fev26'!P469 -> 10128.49 | Q2: 214 | R2: 6.0995 | S2: =Q2*R2 -> 1305.293 | T2: ='Fev26'!Q469 -> -537317.13 | U2: ='Fev26'!R469 -> 50229.3 | V2: ='Fev26'!S469 -> 0 | W2: ='Fev26'!T469 -> 0 | X2: ='Fev26'!U469 -> 0 | Y2: ='Fev26'!V469 -> 0 | Z2: ='Fev26'!W469 -> 0 | AA2: ='Fev26'!X469 -> 0 | ... AR2: ='Fev26'!AO469 -> -369807.9 | AS2: =#REF! -> #REF! | AT2: =#REF! -> #REF! | AU2: =AS2-AT2 -> #REF!
A3: 46082 | B3: BLOCO SPOT
B4: Credito Vendas Cartão | AT4: Saidas | AU4: #REF!
B5: Desconto taxas Cartão | AT5: Saidas | AU5: #REF!
B6: Pix recebido maquininha
B7: Tarifa pix recebido maquinha
B8: BLOCO ITAU
B9: Pix e depositos Vendas
AS10: =#REF! -> #REF!
B11: BLOCO ESTOQUES
B12: Venda de Gasolina | AS12: =#REF! -> #REF!
B13: Venda de Etanol | AS13: =#REF! -> #REF!
B14: Venda de Diesel | AS14: =#REF! -> #REF!
B15: Separação Cartão/Outros | AS15: =#REF! -> #REF!
B16: Ajuste estoque e valor diário (lucro embutido) | AS16: =#REF! -> #REF!
AS17: =#REF! -> #REF!
B18: Saldo Giro no dia | C18: =D19+E19+F19+G19+H19+I19+J19+M19+P19+S19 -> 118585.22 | AR18: =SUM($T2:AQ18) -> -487087.83 | AV18: TERCEIROS
B19: Saldo Líquido do dia | C19: =AR19 -> -368502.61 | D19: =SUM(D2:D18) -> 12717.607 | E19: =SUM(E2:E18) -> -43287.79 | F19: =SUM(F2:F18) -> 0.65 | G19: =SUM(G2:G18) -> 0 | H19: =SUM(H2:H18) -> 65082.293 | I19: =SUM(I2:I18) -> 10004.65 | J19: =SUM(J2:J18) -> 0 | K19: =SUM(K2:K18) -> 12170 | L19: =M19/K19 -> 5.1465924 | M19: =ROUND(SUM(M2:M18),2) -> 62634.03 | N19: =SUM(N2:N18) -> 2783 | O19: =P19/N19 -> 3.6394143 | P19: =ROUND(SUM(P2:P18),2) -> 10128.49 | Q19: =SUM(Q2:Q18) -> 214 | R19: =S19/Q19 -> 6.099486 | S19: =ROUND(SUM(S2:S18),2) -> 1305.29 | T19: =SUM(T2:T18) -> -537317.13 | U19: =SUM(U2:U18) -> 50229.3 | V19: =SUM(V2:V18) -> 0 | W19: =SUM(W2:W18) -> 0 | X19: =SUM(X2:X18) -> 0 | Y19: =SUM(Y2:Y18) -> 0 | Z19: =SUM(Z2:Z18) -> 0 | AA19: =SUM(AA2:AA18) -> 0 | ... AK19: =SUM(AK2:AK18) -> 0 | AM19: =SUM(AM2:AM18) -> 0 | AN19: =SUM(AN2:AN18) -> 0 | AO19: =SUM(AO2:AO18) -> 0 | AP19: =SUM(AP2:AP18) -> 0 | AQ19: =SUM(AQ2:AQ18) -> 0 | AR19: =D19+E19+F19+G19+H19+I19+J19+M19+P19+S19+SUM(T19:AQ19) -> -368502.61 | AV19: CONSOLIDADO
A20: =A3+1 -> 46083 | B20: BLOCO SPOT
B21: Credito Vendas Cartão | AT21: Saidas | AU21: #REF!
B22: Desconto taxas Cartão | AT22: Saidas | AU22: #REF!
B23: Pix recebido maquininha
B24: Tarifa pix recebido maquinha
B25: BLOCO ITAU
B26: Pix e depositos Vendas
AS27: =#REF! -> #REF!
B28: BLOCO ESTOQUES
B29: Venda de Gasolina | AS29: =#REF! -> #REF!
B30: Venda de Etanol | AS30: =#REF! -> #REF!
B31: Venda de Diesel | AS31: =#REF! -> #REF!
B32: Separação Cartão/Outros | AS32: =#REF! -> #REF!
B33: Ajuste estoque e valor diário (lucro embutido) | AS33: =#REF! -> #REF!
AS34: =#REF! -> #REF!
B35: Saldo Giro no dia | C35: =D36+E36+F36+G36+H36+I36+J36+M36+P36 -> 117279.93 | AR35: =SUM($T19:AQ35) -> -487087.83 | AV35: TERCEIROS
B36: Saldo Líquido do dia | C36: =AR36 -> -368502.61 | D36: =SUM(D19:D35) -> 12717.607 | E36: =SUM(E19:E35) -> -43287.79 | F36: =SUM(F19:F35) -> 0.65 | G36: =SUM(G19:G35) -> 0 | H36: =SUM(H19:H35) -> 65082.293 | I36: =SUM(I19:I35) -> 10004.65 | J36: =SUM(J19:J35) -> 0 | K36: =SUM(K19:K35) -> 12170 | L36: =M36/K36 -> 5.1465924 | M36: =ROUND(SUM(M19:M35),2) -> 62634.03 | N36: =SUM(N19:N35) -> 2783 | O36: =P36/N36 -> 3.6394143 | P36: =ROUND(SUM(P19:P35),2) -> 10128.49 | Q36: =SUM(Q19:Q35) -> 214 | R36: =S36/Q36 -> 6.099486 | S36: =ROUND(SUM(S19:S35),2) -> 1305.29 | T36: =SUM(T19:T35) -> -537317.13 | U36: =SUM(U19:U35) -> 50229.3 | V36: =SUM(V19:V35) -> 0 | W36: =SUM(W19:W35) -> 0 | X36: =SUM(X19:X35) -> 0 | Y36: =SUM(Y19:Y35) -> 0 | Z36: =SUM(Z19:Z35) -> 0 | AA36: =SUM(AA19:AA35) -> 0 | ... AQ36: =SUM(AQ19:AQ35) -> 0 | AR36: =D36+E36+F36+G36+H36+I36+J36+M36+P36+S36+SUM(T36:AQ36) -> -368502.61 | AV36: CONSOLIDADO
A37: =A20+1 -> 46084 | B37: BLOCO SPOT
B38: Credito Vendas Cartão | AT38: Saidas | AU38: #REF!
B39: Desconto taxas Cartão | AT39: Saidas | AU39: #REF!
B40: Pix recebido maquininha
...

Sheet Abr26
A1: PERÍODO 01 á 30/ABR/26 | C1: =D2+E2+F2+G2+H2+I2+J2+M2+P2 -> 117279.93 | D1: SPOT | E1: ITAU | F1: LUCILA | G1: HADEN | H1: CAIXA | I1: CARTAO | J1: VENDAS | K1: GASOLINA | N1: ETANOL | Q1: DIESEL | T1: ERALDO | U1: LUIZ F. | V1: LUCILA | W1: DIVIDA | X1: AVANT | Y1: WL | AR1: Total | AS1: Saldo Total | AT1: Saldo Edson | AU1: Saldo Master
B2: Saldo Inicial do dia | C2: =D2+E2+F2+G2+H2+I2+J2+M2+P2+SUM(T2:AQ2) -> -369807.9 | D2: ='Mar26'!D529 -> 12717.607 | E2: ='Mar26'!E529 -> -43287.79 | F2: ='Mar26'!F529 -> 0.65 | G2: ='Mar26'!G529 -> 0 | H2: ='Mar26'!H529 -> 65082.293 | I2: ='Mar26'!I529 -> 10004.65 | J2: ='Mar26'!J529 -> 0 | K2: ='Mar26'!K529 -> 12170 | ... AR2: ='Mar26'!AR529 -> -368502.61 | AS2: =#REF! -> #REF! | AT2: =#REF! -> #REF! | AU2: =AS2-AT2 -> #REF!
A3: 46113 | B3: BLOCO SPOT
B4: Credito Vendas Cartão | AT4: Saidas | AU4: #REF!
B5: Desconto taxas Cartão | AT5: Saidas | AU5: #REF!
B6: Pix recebido maquininha
B7: Tarifa pix recebido maquinha
B8: BLOCO ITAU
B9: Pix e depositos Vendas
AS10: =#REF! -> #REF!
B11: BLOCO ESTOQUES
B12: Venda de Gasolina | AS12: =#REF! -> #REF!
B13: Venda de Etanol | AS13: =#REF! -> #REF!
B14: Venda de Diesel | AS14: =#REF! -> #REF!
B15: Separação Cartão/Outros | AS15: =#REF! -> #REF!
B16: Ajuste estoque e valor diário (lucro embutido) | AS16: =#REF! -> #REF!
AS17: =#REF! -> #REF!
B18: Saldo Giro no dia | C18: =D19+E19+F19+G19+H19+I19+J19+M19+P19+S19 -> 118585.22 | AR18: =SUM($T2:AQ18) -> -487087.83 | AV18: TERCEIROS
B19: Saldo Líquido do dia | C19: =AR19 -> -368502.61 | D19: =SUM(D2:D18) -> 12717.607 | E19: =SUM(E2:E18) -> -43287.79 | F19: =SUM(F2:F18) -> 0.65 | G19: =SUM(G2:G18) -> 0 | H19: =SUM(H2:H18) -> 65082.293 | I19: =SUM(I2:I18) -> 10004.65 | J19: =SUM(J2:J18) -> 0 | K19: =SUM(K2:K18) -> 12170 | L19: =M19/K19 -> 5.1465924 | M19: =ROUND(SUM(M2:M18),2) -> 62634.03 | N19: =SUM(N2:N18) -> 2783 | O19: =P19/N19 -> 3.6394143 | P19: =ROUND(SUM(P2:P18),2) -> 10128.49 | Q19: =SUM(Q2:Q18) -> 214 | R19: =S19/Q19 -> 6.099486 | S19: =ROUND(SUM(S2:S18),2) -> 1305.29 | T19: =SUM(T2:T18) -> -537317.13 | U19: =SUM(U2:U18) -> 50229.3 | V19: =SUM(V2:V18) -> 0 | W19: =SUM(W2:W18) -> 0 | X19: =SUM(X2:X18) -> 0 | Y19: =SUM(Y2:Y18) -> 0 | Z19: =SUM(Z2:Z18) -> 0 | AA19: =SUM(AA2:AA18) -> 0 | ... AK19: =SUM(AK2:AK18) -> 0 | AM19: =SUM(AM2:AM18) -> 0 | AN19: =SUM(AN2:AN18) -> 0 | AO19: =SUM(AO2:AO18) -> 0 | AP19: =SUM(AP2:AP18) -> 0 | AQ19: =SUM(AQ2:AQ18) -> 0 | AR19: =D19+E19+F19+G19+H19+I19+J19+M19+P19+S19+SUM(T19:AQ19) -> -368502.61 | AV19: CONSOLIDADO
A20: =A3+1 -> 46114 | B20: BLOCO SPOT
B21: Credito Vendas Cartão | AT21: Saidas | AU21: #REF!
B22: Desconto taxas Cartão | AT22: Saidas | AU22: #REF!
B23: Pix recebido maquininha
B24: Tarifa pix recebido maquinha
B25: BLOCO ITAU
B26: Pix e depositos Vendas
AS27: =#REF! -> #REF!
B28: BLOCO ESTOQUES
B29: Venda de Gasolina | AS29: =#REF! -> #REF!
B30: Venda de Etanol | AS30: =#REF! -> #REF!
B31: Venda de Diesel | AS31: =#REF! -> #REF!
B32: Separação Cartão/Outros | AS32: =#REF! -> #REF!
B33: Ajuste estoque e valor diário (lucro embutido) | AS33: =#REF! -> #REF!
AS34: =#REF! -> #REF!
B35: Saldo Giro no dia | C35: =D36+E36+F36+G36+H36+I36+J36+M36+P36 -> 117279.93 | AR35: =SUM($T19:AQ35) -> -487087.83 | AV35: TERCEIROS
B36: Saldo Líquido do dia | C36: =AR36 -> -368502.61 | D36: =SUM(D19:D35) -> 12717.607 | E36: =SUM(E19:E35) -> -43287.79 | F36: =SUM(F19:F35) -> 0.65 | G36: =SUM(G19:G35) -> 0 | H36: =SUM(H19:H35) -> 65082.293 | I36: =SUM(I19:I35) -> 10004.65 | J36: =SUM(J19:J35) -> 0 | K36: =SUM(K19:K35) -> 12170 | L36: =M36/K36 -> 5.1465924 | M36: =ROUND(SUM(M19:M35),2) -> 62634.03 | N36: =SUM(N19:N35) -> 2783 | O36: =P36/N36 -> 3.6394143 | P36: =ROUND(SUM(P19:P35),2) -> 10128.49 | Q36: =SUM(Q19:Q35) -> 214 | R36: =S36/Q36 -> 6.099486 | S36: =ROUND(SUM(S19:S35),2) -> 1305.29 | T36: =SUM(T19:T35) -> -537317.13 | U36: =SUM(U19:U35) -> 50229.3 | V36: =SUM(V19:V35) -> 0 | W36: =SUM(W19:W35) -> 0 | X36: =SUM(X19:X35) -> 0 | Y36: =SUM(Y19:Y35) -> 0 | Z36: =SUM(Z19:Z35) -> 0 | AA36: =SUM(AA19:AA35) -> 0 | ... AQ36: =SUM(AQ19:AQ35) -> 0 | AR36: =D36+E36+F36+G36+H36+I36+J36+M36+P36+S36+SUM(T36:AQ36) -> -368502.61 | AV36: CONSOLIDADO
A37: =A20+1 -> 46115 | B37: BLOCO SPOT
B38: Credito Vendas Cartão | AT38: Saidas | AU38: #REF!
B39: Desconto taxas Cartão | AT39: Saidas | AU39: #REF!
B40: Pix recebido maquininha
...

Sheet Mai26
A1: PERÍODO 01 á 31/MAI/26 | C1: =D2+E2+F2+G2+H2+I2+J2+M2+P2 -> 117279.93 | D1: SPOT | E1: ITAU | F1: LUCILA | G1: HADEN | H1: CAIXA | I1: CARTAO | J1: VENDAS | K1: GASOLINA | N1: ETANOL | Q1: DIESEL | T1: ERALDO | U1: LUIZ F. | V1: LUCILA | W1: DIVIDA | X1: AVANT | Y1: WL | AR1: Total | AS1: Saldo Total | AT1: Saldo Edson | AU1: Saldo Master
B2: Saldo Inicial do dia | C2: =D2+E2+F2+G2+H2+I2+J2+M2+P2+SUM(T2:AQ2) -> -369807.9 | D2: ='Abr26'!D529 -> 12717.607 | E2: ='Abr26'!E529 -> -43287.79 | F2: ='Abr26'!F529 -> 0.65 | G2: ='Abr26'!G529 -> 0 | H2: ='Abr26'!H529 -> 65082.293 | I2: ='Abr26'!I529 -> 10004.65 | J2: ='Abr26'!J529 -> 0 | K2: ='Abr26'!K529 -> 12170 | ... AR2: ='Abr26'!AR529 -> -368502.61 | AS2: =#REF! -> #REF! | AT2: =#REF! -> #REF! | AU2: =AS2-AT2 -> #REF!
A3: 46143 | B3: BLOCO SPOT
B4: Credito Vendas Cartão | AT4: Saidas | AU4: #REF!
B5: Desconto taxas Cartão | AT5: Saidas | AU5: #REF!
B6: Pix recebido maquininha
B7: Tarifa pix recebido maquinha
B8: BLOCO ITAU
B9: Pix e depositos Vendas
AS10: =#REF! -> #REF!
B11: BLOCO ESTOQUES
B12: Venda de Gasolina | AS12: =#REF! -> #REF!
B13: Venda de Etanol | AS13: =#REF! -> #REF!
B14: Venda de Diesel | AS14: =#REF! -> #REF!
B15: Separação Cartão/Outros | AS15: =#REF! -> #REF!
B16: Ajuste estoque e valor diário (lucro embutido) | AS16: =#REF! -> #REF!
AS17: =#REF! -> #REF!
B18: Saldo Giro no dia | C18: =D19+E19+F19+G19+H19+I19+J19+M19+P19+S19 -> 118585.22 | AR18: =SUM($T2:AQ18) -> -487087.83 | AV18: TERCEIROS
B19: Saldo Líquido do dia | C19: =AR19 -> -368502.61 | D19: =SUM(D2:D18) -> 12717.607 | E19: =SUM(E2:E18) -> -43287.79 | F19: =SUM(F2:F18) -> 0.65 | G19: =SUM(G2:G18) -> 0 | H19: =SUM(H2:H18) -> 65082.293 | I19: =SUM(I2:I18) -> 10004.65 | J19: =SUM(J2:J18) -> 0 | K19: =SUM(K2:K18) -> 12170 | L19: =M19/K19 -> 5.1465924 | M19: =ROUND(SUM(M2:M18),2) -> 62634.03 | N19: =SUM(N2:N18) -> 2783 | O19: =P19/N19 -> 3.6394143 | P19: =ROUND(SUM(P2:P18),2) -> 10128.49 | Q19: =SUM(Q2:Q18) -> 214 | R19: =S19/Q19 -> 6.099486 | S19: =ROUND(SUM(S2:S18),2) -> 1305.29 | T19: =SUM(T2:T18) -> -537317.13 | U19: =SUM(U2:U18) -> 50229.3 | V19: =SUM(V2:V18) -> 0 | W19: =SUM(W2:W18) -> 0 | X19: =SUM(X2:X18) -> 0 | Y19: =SUM(Y2:Y18) -> 0 | Z19: =SUM(Z2:Z18) -> 0 | AA19: =SUM(AA2:AA18) -> 0 | ... AK19: =SUM(AK2:AK18) -> 0 | AM19: =SUM(AM2:AM18) -> 0 | AN19: =SUM(AN2:AN18) -> 0 | AO19: =SUM(AO2:AO18) -> 0 | AP19: =SUM(AP2:AP18) -> 0 | AQ19: =SUM(AQ2:AQ18) -> 0 | AR19: =D19+E19+F19+G19+H19+I19+J19+M19+P19+S19+SUM(T19:AQ19) -> -368502.61 | AV19: CONSOLIDADO
A20: =A3+1 -> 46144 | B20: BLOCO SPOT
B21: Credito Vendas Cartão | AT21: Saidas | AU21: #REF!
B22: Desconto taxas Cartão | AT22: Saidas | AU22: #REF!
B23: Pix recebido maquininha
B24: Tarifa pix recebido maquinha
B25: BLOCO ITAU
B26: Pix e depositos Vendas
AS27: =#REF! -> #REF!
B28: BLOCO ESTOQUES
B29: Venda de Gasolina | AS29: =#REF! -> #REF!
B30: Venda de Etanol | AS30: =#REF! -> #REF!
B31: Venda de Diesel | AS31: =#REF! -> #REF!
B32: Separação Cartão/Outros | AS32: =#REF! -> #REF!
B33: Ajuste estoque e valor diário (lucro embutido) | AS33: =#REF! -> #REF!
AS34: =#REF! -> #REF!
B35: Saldo Giro no dia | C35: =D36+E36+F36+G36+H36+I36+J36+M36+P36 -> 117279.93 | AR35: =SUM($T19:AQ35) -> -487087.83 | AV35: TERCEIROS
B36: Saldo Líquido do dia | C36: =AR36 -> -368502.61 | D36: =SUM(D19:D35) -> 12717.607 | E36: =SUM(E19:E35) -> -43287.79 | F36: =SUM(F19:F35) -> 0.65 | G36: =SUM(G19:G35) -> 0 | H36: =SUM(H19:H35) -> 65082.293 | I36: =SUM(I19:I35) -> 10004.65 | J36: =SUM(J19:J35) -> 0 | K36: =SUM(K19:K35) -> 12170 | L36: =M36/K36 -> 5.1465924 | M36: =ROUND(SUM(M19:M35),2) -> 62634.03 | N36: =SUM(N19:N35) -> 2783 | O36: =P36/N36 -> 3.6394143 | P36: =ROUND(SUM(P19:P35),2) -> 10128.49 | Q36: =SUM(Q19:Q35) -> 214 | R36: =S36/Q36 -> 6.099486 | S36: =ROUND(SUM(S19:S35),2) -> 1305.29 | T36: =SUM(T19:T35) -> -537317.13 | U36: =SUM(U19:U35) -> 50229.3 | V36: =SUM(V19:V35) -> 0 | W36: =SUM(W19:W35) -> 0 | X36: =SUM(X19:X35) -> 0 | Y36: =SUM(Y19:Y35) -> 0 | Z36: =SUM(Z19:Z35) -> 0 | AA36: =SUM(AA19:AA35) -> 0 | ... AQ36: =SUM(AQ19:AQ35) -> 0 | AR36: =D36+E36+F36+G36+H36+I36+J36+M36+P36+S36+SUM(T36:AQ36) -> -368502.61 | AV36: CONSOLIDADO
A37: =A20+1 -> 46145 | B37: BLOCO SPOT
B38: Credito Vendas Cartão | AT38: Saidas | AU38: #REF!
B39: Desconto taxas Cartão | AT39: Saidas | AU39: #REF!
B40: Pix recebido maquininha
...

Sheet Jun26
A1: PERÍODO 01 á 30/JUN/26 | C1: =D2+E2+F2+G2+H2+I2+J2+M2+P2 -> 117279.93 | D1: SPOT | E1: ITAU | F1: LUCILA | G1: HADEN | H1: CAIXA | I1: CARTAO | J1: VENDAS | K1: GASOLINA | N1: ETANOL | Q1: DIESEL | T1: ERALDO | U1: LUIZ F. | V1: LUCILA | W1: DIVIDA | X1: AVANT | Y1: WL | AR1: Total | AS1: Saldo Total | AT1: Saldo Edson | AU1: Saldo Master
B2: Saldo Inicial do dia | C2: =D2+E2+F2+G2+H2+I2+J2+M2+P2+SUM(T2:AQ2) -> -369807.9 | D2: ='Mai26'!D529 -> 12717.607 | E2: ='Mai26'!E529 -> -43287.79 | F2: ='Mai26'!F529 -> 0.65 | G2: ='Mai26'!G529 -> 0 | H2: ='Mai26'!H529 -> 65082.293 | I2: ='Mai26'!I529 -> 10004.65 | J2: ='Mai26'!J529 -> 0 | K2: ='Mai26'!K529 -> 12170 | ... AR2: ='Mai26'!AR529 -> -368502.61 | AS2: =#REF! -> #REF! | AT2: =#REF! -> #REF! | AU2: =AS2-AT2 -> #REF!
A3: 46174 | B3: BLOCO SPOT
B4: Credito Vendas Cartão | AT4: Saidas | AU4: #REF!
B5: Desconto taxas Cartão | AT5: Saidas | AU5: #REF!
B6: Pix recebido maquininha
B7: Tarifa pix recebido maquinha
B8: BLOCO ITAU
B9: Pix e depositos Vendas
AS10: =#REF! -> #REF!
B11: BLOCO ESTOQUES
B12: Venda de Gasolina | AS12: =#REF! -> #REF!
B13: Venda de Etanol | AS13: =#REF! -> #REF!
B14: Venda de Diesel | AS14: =#REF! -> #REF!
B15: Separação Cartão/Outros | AS15: =#REF! -> #REF!
B16: Ajuste estoque e valor diário (lucro embutido) | AS16: =#REF! -> #REF!
AS17: =#REF! -> #REF!
B18: Saldo Giro no dia | C18: =D19+E19+F19+G19+H19+I19+J19+M19+P19+S19 -> 118585.22 | AR18: =SUM($T2:AQ18) -> -487087.83 | AV18: TERCEIROS
B19: Saldo Líquido do dia | C19: =AR19 -> -368502.61 | D19: =SUM(D2:D18) -> 12717.607 | E19: =SUM(E2:E18) -> -43287.79 | F19: =SUM(F2:F18) -> 0.65 | G19: =SUM(G2:G18) -> 0 | H19: =SUM(H2:H18) -> 65082.293 | I19: =SUM(I2:I18) -> 10004.65 | J19: =SUM(J2:J18) -> 0 | K19: =SUM(K2:K18) -> 12170 | L19: =M19/K19 -> 5.1465924 | M19: =ROUND(SUM(M2:M18),2) -> 62634.03 | N19: =SUM(N2:N18) -> 2783 | O19: =P19/N19 -> 3.6394143 | P19: =ROUND(SUM(P2:P18),2) -> 10128.49 | Q19: =SUM(Q2:Q18) -> 214 | R19: =S19/Q19 -> 6.099486 | S19: =ROUND(SUM(S2:S18),2) -> 1305.29 | T19: =SUM(T2:T18) -> -537317.13 | U19: =SUM(U2:U18) -> 50229.3 | V19: =SUM(V2:V18) -> 0 | W19: =SUM(W2:W18) -> 0 | X19: =SUM(X2:X18) -> 0 | Y19: =SUM(Y2:Y18) -> 0 | Z19: =SUM(Z2:Z18) -> 0 | AA19: =SUM(AA2:AA18) -> 0 | ... AK19: =SUM(AK2:AK18) -> 0 | AM19: =SUM(AM2:AM18) -> 0 | AN19: =SUM(AN2:AN18) -> 0 | AO19: =SUM(AO2:AO18) -> 0 | AP19: =SUM(AP2:AP18) -> 0 | AQ19: =SUM(AQ2:AQ18) -> 0 | AR19: =D19+E19+F19+G19+H19+I19+J19+M19+P19+S19+SUM(T19:AQ19) -> -368502.61 | AV19: CONSOLIDADO
A20: =A3+1 -> 46175 | B20: BLOCO SPOT
B21: Credito Vendas Cartão | AT21: Saidas | AU21: #REF!
B22: Desconto taxas Cartão | AT22: Saidas | AU22: #REF!
B23: Pix recebido maquininha
B24: Tarifa pix recebido maquinha
B25: BLOCO ITAU
B26: Pix e depositos Vendas
AS27: =#REF! -> #REF!
B28: BLOCO ESTOQUES
B29: Venda de Gasolina | AS29: =#REF! -> #REF!
B30: Venda de Etanol | AS30: =#REF! -> #REF!
B31: Venda de Diesel | AS31: =#REF! -> #REF!
B32: Separação Cartão/Outros | AS32: =#REF! -> #REF!
B33: Ajuste estoque e valor diário (lucro embutido) | AS33: =#REF! -> #REF!
AS34: =#REF! -> #REF!
B35: Saldo Giro no dia | C35: =D36+E36+F36+G36+H36+I36+J36+M36+P36 -> 117279.93 | AR35: =SUM($T19:AQ35) -> -487087.83 | AV35: TERCEIROS
B36: Saldo Líquido do dia | C36: =AR36 -> -368502.61 | D36: =SUM(D19:D35) -> 12717.607 | E36: =SUM(E19:E35) -> -43287.79 | F36: =SUM(F19:F35) -> 0.65 | G36: =SUM(G19:G35) -> 0 | H36: =SUM(H19:H35) -> 65082.293 | I36: =SUM(I19:I35) -> 10004.65 | J36: =SUM(J19:J35) -> 0 | K36: =SUM(K19:K35) -> 12170 | L36: =M36/K36 -> 5.1465924 | M36: =ROUND(SUM(M19:M35),2) -> 62634.03 | N36: =SUM(N19:N35) -> 2783 | O36: =P36/N36 -> 3.6394143 | P36: =ROUND(SUM(P19:P35),2) -> 10128.49 | Q36: =SUM(Q19:Q35) -> 214 | R36: =S36/Q36 -> 6.099486 | S36: =ROUND(SUM(S19:S35),2) -> 1305.29 | T36: =SUM(T19:T35) -> -537317.13 | U36: =SUM(U19:U35) -> 50229.3 | V36: =SUM(V19:V35) -> 0 | W36: =SUM(W19:W35) -> 0 | X36: =SUM(X19:X35) -> 0 | Y36: =SUM(Y19:Y35) -> 0 | Z36: =SUM(Z19:Z35) -> 0 | AA36: =SUM(AA19:AA35) -> 0 | ... AQ36: =SUM(AQ19:AQ35) -> 0 | AR36: =D36+E36+F36+G36+H36+I36+J36+M36+P36+S36+SUM(T36:AQ36) -> -368502.61 | AV36: CONSOLIDADO
A37: =A20+1 -> 46176 | B37: BLOCO SPOT
B38: Credito Vendas Cartão | AT38: Saidas | AU38: #REF!
B39: Desconto taxas Cartão | AT39: Saidas | AU39: #REF!
B40: Pix recebido maquininha
...

Sheet Jul26
A1: PERÍODO 01 á 31/JUL/26 | C1: =D2+E2+F2+G2+H2+I2+J2+M2+P2 -> 117279.93 | D1: SPOT | E1: ITAU | F1: LUCILA | G1: HADEN | H1: CAIXA | I1: CARTAO | J1: VENDAS | K1: GASOLINA | N1: ETANOL | Q1: DIESEL | T1: ERALDO | U1: LUIZ F. | V1: LUCILA | W1: DIVIDA | X1: AVANT | Y1: WL | AR1: Total | AS1: Saldo Total | AT1: Saldo Edson | AU1: Saldo Master
B2: Saldo Inicial do dia | C2: =D2+E2+F2+G2+H2+I2+J2+M2+P2+SUM(T2:AQ2) -> -369807.9 | D2: ='Jun26'!D529 -> 12717.607 | E2: ='Jun26'!E529 -> -43287.79 | F2: ='Jun26'!F529 -> 0.65 | G2: ='Jun26'!G529 -> 0 | H2: ='Jun26'!H529 -> 65082.293 | I2: ='Jun26'!I529 -> 10004.65 | J2: ='Jun26'!J529 -> 0 | K2: ='Jun26'!K529 -> 12170 | ... AR2: ='Jun26'!AR529 -> -368502.61 | AS2: =#REF! -> #REF! | AT2: =#REF! -> #REF! | AU2: =AS2-AT2 -> #REF!
A3: 46204 | B3: BLOCO SPOT
B4: Credito Vendas Cartão | AT4: Saidas | AU4: #REF!
B5: Desconto taxas Cartão | AT5: Saidas | AU5: #REF!
B6: Pix recebido maquininha
B7: Tarifa pix recebido maquinha
B8: BLOCO ITAU
B9: Pix e depositos Vendas
AS10: =#REF! -> #REF!
B11: BLOCO ESTOQUES
B12: Venda de Gasolina | AS12: =#REF! -> #REF!
B13: Venda de Etanol | AS13: =#REF! -> #REF!
B14: Venda de Diesel | AS14: =#REF! -> #REF!
B15: Separação Cartão/Outros | AS15: =#REF! -> #REF!
B16: Ajuste estoque e valor diário (lucro embutido) | AS16: =#REF! -> #REF!
AS17: =#REF! -> #REF!
B18: Saldo Giro no dia | C18: =D19+E19+F19+G19+H19+I19+J19+M19+P19+S19 -> 118585.22 | AR18: =SUM($T2:AQ18) -> -487087.83 | AV18: TERCEIROS
B19: Saldo Líquido do dia | C19: =AR19 -> -368502.61 | D19: =SUM(D2:D18) -> 12717.607 | E19: =SUM(E2:E18) -> -43287.79 | F19: =SUM(F2:F18) -> 0.65 | G19: =SUM(G2:G18) -> 0 | H19: =SUM(H2:H18) -> 65082.293 | I19: =SUM(I2:I18) -> 10004.65 | J19: =SUM(J2:J18) -> 0 | K19: =SUM(K2:K18) -> 12170 | L19: =M19/K19 -> 5.1465924 | M19: =ROUND(SUM(M2:M18),2) -> 62634.03 | N19: =SUM(N2:N18) -> 2783 | O19: =P19/N19 -> 3.6394143 | P19: =ROUND(SUM(P2:P18),2) -> 10128.49 | Q19: =SUM(Q2:Q18) -> 214 | R19: =S19/Q19 -> 6.099486 | S19: =ROUND(SUM(S2:S18),2) -> 1305.29 | T19: =SUM(T2:T18) -> -537317.13 | U19: =SUM(U2:U18) -> 50229.3 | V19: =SUM(V2:V18) -> 0 | W19: =SUM(W2:W18) -> 0 | X19: =SUM(X2:X18) -> 0 | Y19: =SUM(Y2:Y18) -> 0 | Z19: =SUM(Z2:Z18) -> 0 | AA19: =SUM(AA2:AA18) -> 0 | ... AK19: =SUM(AK2:AK18) -> 0 | AM19: =SUM(AM2:AM18) -> 0 | AN19: =SUM(AN2:AN18) -> 0 | AO19: =SUM(AO2:AO18) -> 0 | AP19: =SUM(AP2:AP18) -> 0 | AQ19: =SUM(AQ2:AQ18) -> 0 | AR19: =D19+E19+F19+G19+H19+I19+J19+M19+P19+S19+SUM(T19:AQ19) -> -368502.61 | AV19: CONSOLIDADO
A20: =A3+1 -> 46205 | B20: BLOCO SPOT
B21: Credito Vendas Cartão | AT21: Saidas | AU21: #REF!
B22: Desconto taxas Cartão | AT22: Saidas | AU22: #REF!
B23: Pix recebido maquininha
B24: Tarifa pix recebido maquinha
B25: BLOCO ITAU
B26: Pix e depositos Vendas
AS27: =#REF! -> #REF!
B28: BLOCO ESTOQUES
B29: Venda de Gasolina | AS29: =#REF! -> #REF!
B30: Venda de Etanol | AS30: =#REF! -> #REF!
B31: Venda de Diesel | AS31: =#REF! -> #REF!
B32: Separação Cartão/Outros | AS32: =#REF! -> #REF!
B33: Ajuste estoque e valor diário (lucro embutido) | AS33: =#REF! -> #REF!
AS34: =#REF! -> #REF!
B35: Saldo Giro no dia | C35: =D36+E36+F36+G36+H36+I36+J36+M36+P36 -> 117279.93 | AR35: =SUM($T19:AQ35) -> -487087.83 | AV35: TERCEIROS
B36: Saldo Líquido do dia | C36: =AR36 -> -368502.61 | D36: =SUM(D19:D35) -> 12717.607 | E36: =SUM(E19:E35) -> -43287.79 | F36: =SUM(F19:F35) -> 0.65 | G36: =SUM(G19:G35) -> 0 | H36: =SUM(H19:H35) -> 65082.293 | I36: =SUM(I19:I35) -> 10004.65 | J36: =SUM(J19:J35) -> 0 | K36: =SUM(K19:K35) -> 12170 | L36: =M36/K36 -> 5.1465924 | M36: =ROUND(SUM(M19:M35),2) -> 62634.03 | N36: =SUM(N19:N35) -> 2783 | O36: =P36/N36 -> 3.6394143 | P36: =ROUND(SUM(P19:P35),2) -> 10128.49 | Q36: =SUM(Q19:Q35) -> 214 | R36: =S36/Q36 -> 6.099486 | S36: =ROUND(SUM(S19:S35),2) -> 1305.29 | T36: =SUM(T19:T35) -> -537317.13 | U36: =SUM(U19:U35) -> 50229.3 | V36: =SUM(V19:V35) -> 0 | W36: =SUM(W19:W35) -> 0 | X36: =SUM(X19:X35) -> 0 | Y36: =SUM(Y19:Y35) -> 0 | Z36: =SUM(Z19:Z35) -> 0 | AA36: =SUM(AA19:AA35) -> 0 | ... AQ36: =SUM(AQ19:AQ35) -> 0 | AR36: =D36+E36+F36+G36+H36+I36+J36+M36+P36+S36+SUM(T36:AQ36) -> -368502.61 | AV36: CONSOLIDADO
A37: =A20+1 -> 46206 | B37: BLOCO SPOT
B38: Credito Vendas Cartão | AT38: Saidas | AU38: #REF!
B39: Desconto taxas Cartão | AT39: Saidas | AU39: #REF!
B40: Pix recebido maquininha
...

Sheet Ago26
A1: PERÍODO 01 á 31/AGO/26 | C1: =D2+E2+F2+G2+H2+I2+J2+M2+P2 -> 117279.93 | D1: SPOT | E1: ITAU | F1: LUCILA | G1: HADEN | H1: CAIXA | I1: CARTAO | J1: VENDAS | K1: GASOLINA | N1: ETANOL | Q1: DIESEL | T1: ERALDO | U1: LUIZ F. | V1: LUCILA | W1: DIVIDA | X1: AVANT | Y1: WL | AR1: Total | AS1: Saldo Total | AT1: Saldo Edson | AU1: Saldo Master
B2: Saldo Inicial do dia | C2: =D2+E2+F2+G2+H2+I2+J2+M2+P2+SUM(T2:AQ2) -> -369807.9 | D2: ='Jul26'!D529 -> 12717.607 | E2: ='Jul26'!E529 -> -43287.79 | F2: ='Jul26'!F529 -> 0.65 | G2: ='Jul26'!G529 -> 0 | H2: ='Jul26'!H529 -> 65082.293 | I2: ='Jul26'!I529 -> 10004.65 | J2: ='Jul26'!J529 -> 0 | K2: ='Jul26'!K529 -> 12170 | ... AR2: ='Jul26'!AR529 -> -368502.61 | AS2: =#REF! -> #REF! | AT2: =#REF! -> #REF! | AU2: =AS2-AT2 -> #REF!
A3: 46235 | B3: BLOCO SPOT
B4: Credito Vendas Cartão | AT4: Saidas | AU4: #REF!
B5: Desconto taxas Cartão | AT5: Saidas | AU5: #REF!
B6: Pix recebido maquininha
B7: Tarifa pix recebido maquinha
B8: BLOCO ITAU
B9: Pix e depositos Vendas
AS10: =#REF! -> #REF!
B11: BLOCO ESTOQUES
B12: Venda de Gasolina | AS12: =#REF! -> #REF!
B13: Venda de Etanol | AS13: =#REF! -> #REF!
B14: Venda de Diesel | AS14: =#REF! -> #REF!
B15: Separação Cartão/Outros | AS15: =#REF! -> #REF!
B16: Ajuste estoque e valor diário (lucro embutido) | AS16: =#REF! -> #REF!
AS17: =#REF! -> #REF!
B18: Saldo Giro no dia | C18: =D19+E19+F19+G19+H19+I19+J19+M19+P19+S19 -> 118585.22 | AR18: =SUM($T2:AQ18) -> -487087.83 | AV18: TERCEIROS
B19: Saldo Líquido do dia | C19: =AR19 -> -368502.61 | D19: =SUM(D2:D18) -> 12717.607 | E19: =SUM(E2:E18) -> -43287.79 | F19: =SUM(F2:F18) -> 0.65 | G19: =SUM(G2:G18) -> 0 | H19: =SUM(H2:H18) -> 65082.293 | I19: =SUM(I2:I18) -> 10004.65 | J19: =SUM(J2:J18) -> 0 | K19: =SUM(K2:K18) -> 12170 | L19: =M19/K19 -> 5.1465924 | M19: =ROUND(SUM(M2:M18),2) -> 62634.03 | N19: =SUM(N2:N18) -> 2783 | O19: =P19/N19 -> 3.6394143 | P19: =ROUND(SUM(P2:P18),2) -> 10128.49 | Q19: =SUM(Q2:Q18) -> 214 | R19: =S19/Q19 -> 6.099486 | S19: =ROUND(SUM(S2:S18),2) -> 1305.29 | T19: =SUM(T2:T18) -> -537317.13 | U19: =SUM(U2:U18) -> 50229.3 | V19: =SUM(V2:V18) -> 0 | W19: =SUM(W2:W18) -> 0 | X19: =SUM(X2:X18) -> 0 | Y19: =SUM(Y2:Y18) -> 0 | Z19: =SUM(Z2:Z18) -> 0 | AA19: =SUM(AA2:AA18) -> 0 | ... AK19: =SUM(AK2:AK18) -> 0 | AM19: =SUM(AM2:AM18) -> 0 | AN19: =SUM(AN2:AN18) -> 0 | AO19: =SUM(AO2:AO18) -> 0 | AP19: =SUM(AP2:AP18) -> 0 | AQ19: =SUM(AQ2:AQ18) -> 0 | AR19: =D19+E19+F19+G19+H19+I19+J19+M19+P19+S19+SUM(T19:AQ19) -> -368502.61 | AV19: CONSOLIDADO
A20: =A3+1 -> 46236 | B20: BLOCO SPOT
B21: Credito Vendas Cartão | AT21: Saidas | AU21: #REF!
B22: Desconto taxas Cartão | AT22: Saidas | AU22: #REF!
B23: Pix recebido maquininha
B24: Tarifa pix recebido maquinha
B25: BLOCO ITAU
B26: Pix e depositos Vendas
AS27: =#REF! -> #REF!
B28: BLOCO ESTOQUES
B29: Venda de Gasolina | AS29: =#REF! -> #REF!
B30: Venda de Etanol | AS30: =#REF! -> #REF!
B31: Venda de Diesel | AS31: =#REF! -> #REF!
B32: Separação Cartão/Outros | AS32: =#REF! -> #REF!
